package gregtechlite.gtlitecore.common.metatileentity.multiblock.module

import gregtech.api.metatileentity.MetaTileEntity
import gregtech.api.metatileentity.interfaces.IGregTechTileEntity
import gregtech.api.metatileentity.multiblock.IMultiblockPart
import gregtech.api.pattern.BlockPattern
import gregtech.api.pattern.FactoryBlockPattern
import gregtech.api.unification.material.Materials.Neutronium
import gregtech.api.util.RelativeDirection.DOWN
import gregtech.api.util.RelativeDirection.FRONT
import gregtech.api.util.RelativeDirection.RIGHT
import gregtech.client.renderer.ICubeRenderer
import gregtechlite.gtlitecore.api.metatileentity.multiblock.extendable.AdditionalMultiblockBase
import gregtechlite.gtlitecore.api.unification.GTLiteMaterials.Bedrockium
import gregtechlite.gtlitecore.api.unification.GTLiteMaterials.TranscendentMetal
import gregtechlite.gtlitecore.client.renderer.texture.GTLiteOverlays
import gregtechlite.gtlitecore.common.block.variant.GlassCasing
import gregtechlite.gtlitecore.common.block.variant.MetalCasing
import gregtechlite.gtlitecore.common.block.variant.MultiblockCasing
import gregtechlite.gtlitecore.common.block.variant.fusion.FusionCoil
import gregtechlite.gtlitecore.common.block.variant.science.ScienceCasing
import gregtechlite.gtlitecore.common.metatileentity.multiblock.MultiblockNanoForge
import net.minecraft.client.resources.I18n
import net.minecraft.item.ItemStack
import net.minecraft.util.ResourceLocation
import net.minecraft.world.World
import net.minecraftforge.fml.relauncher.Side
import net.minecraftforge.fml.relauncher.SideOnly

class MultiblockVirtualGestaltComputingUplink<T : MultiblockNanoForge<T>>(id: ResourceLocation) : AdditionalMultiblockBase<T>(id)
{
    companion object
    {
        private val casingState = MultiblockCasing.LATTICE_QCD_THERMAL_SHIELDING_CASING.state
        private val secondCasingState = MetalCasing.NEUTRONIUM.state
        private val thirdCasingState = MultiblockCasing.GRAVITY_STABILIZATION_CASING.state
        private val fourthCasingState = ScienceCasing.DIMENSIONAL_BRIDGE_CASING.state
        private val glassState = GlassCasing.NANO_SHIELDING_FRAME.state
        private val coilState = FusionCoil.ULTIMATE.state
    }

    override fun createMetaTileEntity(te: IGregTechTileEntity): MetaTileEntity
        = MultiblockVirtualGestaltComputingUplink(metaTileEntityId)

    override fun updateFormedValid()
    {
        mainController?.addAdditional(this)
    }

    // @formatter:off

    override fun createStructurePattern(): BlockPattern = FactoryBlockPattern.start(RIGHT, FRONT, DOWN)
        .aisle("                MMMMMMMMM                ", "             MMM         MMM             ", "           MM               MM           ", "         MM                   MM         ", "        M                       M        ", "       M                         M       ", "      M                           M      ", "     M                             M     ", "    M                               M    ", "   M                                 M   ", "   M                                 M   ", "  M                                   M  ", "  M                                   M  ", " M                                     M ", " M                                     M ", " M                                     M ", "M                  RRR                  M", "M                RRRRRRR                M", "M                RRRRRRR                M", "M               RRRRRRRRR               M", "M               RRRRRRRRR               M", "M               RRRRRRRRR               M", "M                RRRRRRR                M", "M                RRRRRRR                M", "M                  RRR                  M", " M                                     M ", " M                                     M ", " M                                     M ", "  M                                   M  ", "  M                                   M  ", "   M                                 M   ", "   M                                 M   ", "    M                               M    ", "     M                             M     ", "      M                           M      ", "       M                         M       ", "        M                       M        ", "         MM                   MM         ", "           MM               MM           ", "             MMM         MMM             ", "                MMMMMMMMM                ")
        .aisle("                    M                    ", "                                         ", "                                         ", "                                         ", "                                         ", "                                         ", "                                         ", "                                         ", "                                         ", "                                         ", "                                         ", "                                         ", "                    R                    ", "                 RRRRRRR                 ", "                RRRRRRRRR                ", "               RRRR   RRRR               ", "              RRR       RRR              ", "              RRR       RRR              ", "              RR         RR              ", "             RRR         RRR             ", "M             RR         RR             M", "              RRR       RRR              ", "              RRR       RRR              ", "               RRRR   RRRR               ", "                RRRRRRRRR                ", "                 RRRRRRR                 ", "                    R                    ", "                                         ", "                                         ", "                                         ", "                                         ", "                                         ", "                                         ", "                                         ", "                                         ", "                                         ", "                                         ", "                                         ", "                                         ", "                                         ", "                    M                    ")
        .aisle("                    M                    ", "                                         ", "                                         ", "                                         ", "                                         ", "                                         ", "                                         ", "                                         ", "                                         ", "                                         ", "                                         ", "                                         ", "                 RRRRRRR                 ", "               RRRRR RRRRR               ", "              RRR       RRR              ", "             RRR         RRR             ", "             RR           RR             ", "            RR             RR            ", "            RR             RR            ", "            RR             RR            ", "M           R               R           M", "            RR             RR            ", "            RR             RR            ", "            RR             RR            ", "             RR           RR             ", "             RRR         RRR             ", "              RRR       RRR              ", "               RRRRR RRRRR               ", "                 RRRRRRR                 ", "                                         ", "                                         ", "                                         ", "                                         ", "                                         ", "                                         ", "                                         ", "                                         ", "                                         ", "                                         ", "                                         ", "                    M                    ")
        .aisle("                    M                    ", "                                         ", "                                         ", "                                         ", "                                         ", "                                         ", "                                         ", "                                         ", "                                         ", "                                         ", "                 RRRRRRR                 ", "               RRRRRRRRRRR               ", "              RRR       RRR              ", "             RR           RR             ", "            RR             RR            ", "           RR               RR           ", "           RR               RR           ", "          RR                 RR          ", "          RR                 RR          ", "          RR                 RR          ", "M         RR                 RR         M", "          RR                 RR          ", "          RR                 RR          ", "          RR                 RR          ", "           RR               RR           ", "           RR               RR           ", "            RR             RR            ", "             RR           RR             ", "              RRR       RRR              ", "               RRRRRRRRRRR               ", "                 RRRRRRR                 ", "                                         ", "                                         ", "                                         ", "                                         ", "                                         ", "                                         ", "                                         ", "                                         ", "                                         ", "                    M                    ")
        .aisle("                    M                    ", "                                         ", "                                         ", "                                         ", "                                         ", "                                         ", "                                         ", "                                         ", "                                         ", "                RRRRRRRRR                ", "              RRR       RRR              ", "             RR           RR             ", "            RR             RR            ", "           RR               RR           ", "          RR                 RR          ", "          R                   R          ", "         RR                   RR         ", "         R                     R         ", "         R                     R         ", "         R       JJJJJJJ       R         ", "M        R       JJJJJJJ       R        M", "         R       JJJJJJJ       R         ", "         R                     R         ", "         R                     R         ", "         RR                   RR         ", "          R                   R          ", "          RR                 RR          ", "           RR               RR           ", "            RR             RR            ", "             RR           RR             ", "              RRR       RRR              ", "                RRRRRRRRR                ", "                                         ", "                                         ", "                                         ", "                                         ", "                                         ", "                                         ", "                                         ", "                                         ", "                    M                    ")
        .aisle("                                         ", "                MMMMMMMMM                ", "             MMM         MMM             ", "           MM               MM           ", "         MM                   MM         ", "        M                       M        ", "       M                         M       ", "      M                           M      ", "     M          RRRRRRRRR          M     ", "    M         RR         RR         M    ", "    M        R             R        M    ", "   M        R               R        M   ", "   M       R                 R       M   ", "  M       R                   R       M  ", "  M      R                     R      M  ", "  M      R                     R      M  ", " M      R                       R      M ", " M      R                       R      M ", " M      R                       R      M ", " M      R     JJJJJJJJJJJJJ     R      M ", " M      R     JJJJJJJJJJJJJ     R      M ", " M      R     JJJJJJJJJJJJJ     R      M ", " M      R                       R      M ", " M      R                       R      M ", " M      R                       R      M ", "  M      R                     R      M  ", "  M      R                     R      M  ", "  M       R                   R       M  ", "   M       R                 R       M   ", "   M        R               R        M   ", "    M        R             R        M    ", "    M         RR         RR         M    ", "     M          RRRRRRRRR          M     ", "      M                           M      ", "       M                         M       ", "        M                       M        ", "         MM                   MM         ", "           MM               MM           ", "             MMM         MMM             ", "                MMMMMMMMM                ", "                                         ")
        .aisle("                                         ", "                    M                    ", "                                         ", "                                         ", "                                         ", "                                         ", "                                         ", "                 RRRRRRR                 ", "              RRR       RRR              ", "             R             R             ", "           RR               RR           ", "          RR                 RR          ", "          R                   R          ", "         R                     R         ", "        R                       R        ", "        R                       R        ", "        R                        R       ", "       R                         R       ", "       R                         R       ", "       R     JJJJ       JJJJ     R       ", " M     R     JJJJ       JJJJ     R     M ", "       R     JJJJ       JJJJ     R       ", "       R                         R       ", "       R                         R       ", "       R                         R       ", "        R                       R        ", "        R                       R        ", "         R                     R         ", "          R                   R          ", "          RR                 RR          ", "           RR               RR           ", "             R             R             ", "              RR         RR              ", "                RRRRRRRRR                ", "                                         ", "                                         ", "                                         ", "                                         ", "                                         ", "                    M                    ", "                                         ")
        .aisle("                                         ", "                    M                    ", "                                         ", "                                         ", "                                         ", "                                         ", "                 RRRRRRR                 ", "              RRR       RRR              ", "             R             R             ", "           RR               RR           ", "          R                   R          ", "         R                     R         ", "         R                     R         ", "        R                       R        ", "       R                         R       ", "       R                         R       ", "       R                         R       ", "      R            JJJ            R      ", "      R            JJJ            R      ", "      R    JJJJ    JJJ    JJJJ    R      ", " M    R    JJJJ    JJJ    JJJJ    R    M ", "      R    JJJJ    JJJ    JJJJ    R      ", "      R            JJJ            R      ", "      R            JJJ            R      ", "       R                         R       ", "       R                         R       ", "       R                         R       ", "        R                       R        ", "         R                     R         ", "         R                     R         ", "          R                   R          ", "           RR               RR           ", "             R             R             ", "              RR        RRR              ", "                RRRRRRRR                 ", "                                         ", "                                         ", "                                         ", "                                         ", "                    M                    ", "                                         ")
        .aisle("                                         ", "                                         ", "                    M                    ", "                                         ", "                                         ", "                                         ", "               RRRRRRRRRRR               ", "             RR           RR             ", "            R               R            ", "          RR                 RR          ", "         R                     R         ", "         R                     R         ", "        R                       R        ", "       R                         R       ", "       R                         R       ", "      R            JJJ            R      ", "      R            JJJ            R      ", "      R            JJJ            R      ", "      R            JJJ            R      ", "      R   JJJ      JJJ      JJJ   R      ", "  M   R   JJJ      JJJ      JJJ   R   M  ", "      R   JJJ      JJJ      JJJ   R      ", "      R            JJJ            R      ", "      R            JJJ            R      ", "      R            JJJ            R      ", "      R            JJJ            R      ", "       R                         R       ", "       R                         R       ", "        R                       R        ", "         R                     R         ", "         R                     R         ", "          RR                 RR          ", "            R               R            ", "             RR           RR             ", "               RRRRRRRRRRR               ", "                                         ", "                                         ", "                                         ", "                    M                    ", "                                         ", "                                         ")
        .aisle("                                         ", "                                         ", "                    M                    ", "                                         ", "                                         ", "                 RRRRRRR                 ", "              RRR       RRR              ", "            RR             RR            ", "           R                 R           ", "          R                   R          ", "         R                     R         ", "        R                       R        ", "       R                         R       ", "       R                         R       ", "      R            JJJ            R      ", "      R            JJJ            R      ", "      R            JJJ            R      ", "     R                             R     ", "     R                             R     ", "     R    JJ                 JJ    R     ", "  M  R    JJ                 JJ    R  M  ", "     R    JJ                 JJ    R     ", "     R                             R     ", "     R                             R     ", "      R            JJJ            R      ", "      R            JJJ            R      ", "      R            JJJ            R      ", "       R                         R       ", "       R                         R       ", "        R                       R        ", "         R                     R         ", "          R                   R          ", "           R                 R           ", "            RR             RR            ", "              RRR       RRR              ", "                 RRRRRRR                 ", "                                         ", "                                         ", "                    M                    ", "                                         ", "                                         ")
        .aisle("                                         ", "                                         ", "                                         ", "                MMMMMMMMM                ", "             MMM    R    MMM             ", "           MM  RRRRR RRRRR  MMM          ", "          M  RR           RR  M          ", "         M RR               RR M         ", "        M R                   R M        ", "       M R                     R M       ", "      M R                       R M      ", "     M R                         R M     ", "     M R                         R M     ", "    M R            JJJ            R M    ", "    M R            JJJ            R M    ", "    MR                             RM    ", "   M R                             R M   ", "   M R                             R M   ", "   M R                             R M   ", "   M R   JJ                   JJ   R M   ", "   MR    JJ                   JJ    RM   ", "   M R   JJ                   JJ   R M   ", "   M R                             R M   ", "   M R                             R M   ", "   M R                             R M   ", "    MR                             RM    ", "    M R            JJJ            R M    ", "    M R            JJJ            R M    ", "     M R                         R M     ", "     M R                         R M     ", "      M R                       R M      ", "       M R                     R M       ", "        M R                   R M        ", "         M RR               RR M         ", "          M  RR           RR  M          ", "           MM  RRRRR RRRRR  MM           ", "             MMM    R    MMM             ", "                MMMMMMMMM                ", "                                         ", "                                         ", "                                         ")
        .aisle("                                         ", "                                         ", "                                         ", "                    M                    ", "                 RRRRRRR                 ", "              RRR       RRR              ", "            RR             RR            ", "          RR                 RR          ", "         R                     R         ", "        R                       R        ", "       R                         R       ", "       R                         R       ", "      R            JJJ            R      ", "      R            JJJ            R      ", "     R                             R     ", "     R                             R     ", "     R                             R     ", "    R                               R    ", "    R                               R    ", "    R   JJJ                   JJJ   R    ", "   MR   JJJ                   JJJ   RM   ", "    R   JJJ                   JJJ   R    ", "    R                               R    ", "    R                               R    ", "     R                             R     ", "     R                             R     ", "     R                             R     ", "      R            JJJ            R      ", "      R            JJJ            R      ", "       R                         R       ", "       R                         R       ", "        R                       R        ", "         R                     R         ", "          RR                 RR          ", "            RR             RR            ", "              RRR       RRR              ", "                 RRRRRRR                 ", "                    M                    ", "                                         ", "                                         ", "                                         ")
        .aisle("                                         ", "                                         ", "                                         ", "                                         ", "                RRRRRRRRR                ", "             RRR         RRR             ", "           RR               RR           ", "          R                   R          ", "         R                     R         ", "        R                       R        ", "       R                         R       ", "      R            JJJ            R      ", "      R            JJJ            R      ", "     R                             R     ", "     R                             R     ", "     R                             R     ", "    R                               R    ", "    R                               R    ", "    R                               R    ", "    R   JJ                     JJ   R    ", "    R   JJ                     JJ   R    ", "    R   JJ                     JJ   R    ", "    R                               R    ", "    R                               R    ", "    R                               R    ", "     R                             R     ", "     R                             R     ", "     R                             R     ", "      R            JJJ            R      ", "      R            JJJ            R      ", "       R                         R       ", "        R                       R        ", "         R                     R         ", "          R                   R          ", "           RR               RR           ", "             RRR         RRR             ", "                RRRRRRRRR                ", "                                         ", "                                         ", "                                         ", "                                         ")
        .aisle("                                         ", "                                         ", "                                         ", "                   RRR                   ", "               RRRR   RRRR               ", "             RR     M     RR             ", "           RR               RR           ", "         RR                   RR         ", "        R                       R        ", "       R                         R       ", "       R                         R       ", "      R            JJJ            R      ", "      R            JJJ            R      ", "     R                             R     ", "     R                             R     ", "    R                               R    ", "    R                               R    ", "    R                               R    ", "    R                               R    ", "   R    JJ         RRR         JJ    R   ", "   R M  JJ         RRR         JJ  M R   ", "   R    JJ         RRR         JJ    R   ", "    R                               R    ", "    R                               R    ", "    R                               R    ", "    R                               R    ", "     R                             R     ", "     R                             R     ", "      R            JJJ            R      ", "      R            JJJ            R      ", "       R                         R       ", "       R                         R       ", "        R                       R        ", "         RR                   RR         ", "           RR               RR           ", "             RR     M     RR             ", "               RRRR   RRRR               ", "                   RRR                   ", "                                         ", "                                         ", "                                         ")
        .aisle("                                         ", "                                         ", "                                         ", "                 RRRRRRR                 ", "              RRR       RRR              ", "            RR   MMMMMMM   RR            ", "          RR  MMM   M   MMM  RR          ", "         R  MM             MM  R         ", "        R  M                 M  R        ", "       R  M                   M  R       ", "      R  M         JJJ         M  R      ", "      R M          JJJ          M R      ", "     R M                         M R     ", "     R M                         M R     ", "    R M                           M R    ", "    R M                           M R    ", "    R M                           M R    ", "   R M                             M R   ", "   R M             RRR             M R   ", "   R M JJ         RQQQR         JJ M R   ", "   R MMJJ         RQQQR         JJMM R   ", "   R M JJ         RQQQR         JJ M R   ", "   R M             RRR             M R   ", "   R M                             M R   ", "    R M                           M R    ", "    R M                           M R    ", "    R M                           M R    ", "     R M                         M R     ", "     R M                         M R     ", "      R M          JJJ          M R      ", "      R  M         JJJ         M  R      ", "       R  M                   M  R       ", "        R  M                 M  R        ", "         R  MM             MM  R         ", "          RR  MMM   M   MMM  RR          ", "            RR   MMMMMMM   RR            ", "              RRR       RRR              ", "                 RRRRRRR                 ", "                                         ", "                                         ", "                                         ")
        .aisle("                                         ", "                                         ", "                                         ", "                 RRRRRRR                 ", "              RRR       RRR              ", "            RR             RR            ", "          RR    M   M   M    RR          ", "         R                     R         ", "        R                       R        ", "       R M                     M R       ", "      R            JJJ            R      ", "      R            JJJ            R      ", "     R                             R     ", "     R                             R     ", "    R                               R    ", "    R                               R    ", "    R M                           M R    ", "   R               RRR               R   ", "   R              RQQQR              R   ", "   R   JJ        RQQQQQR        JJ   R   ", "   R  MJJ        RQQQQQR        JJM  R   ", "   R   JJ        RQQQQQR        JJ   R   ", "   R              RQQQR              R   ", "   R               RRR               R   ", "    R M                           M R    ", "    R                               R    ", "    R                               R    ", "     R                             R     ", "     R                             R     ", "      R            JJJ            R      ", "      R            JJJ            R      ", "       R M                     M R       ", "        R                       R        ", "         R                     R         ", "          RR    M   M   M    RR          ", "            RR             RR            ", "              RRR       RRR              ", "                 RRRRRRR                 ", "                                         ", "                                         ", "                                         ")
        .aisle("                                         ", "                                         ", "                                         ", "                RRRRRRRRR                ", "              RR         RR              ", "            RR             RR            ", "          RR     M  J  M     RR          ", "         R                     R         ", "        RM                      R        ", "       R M                    MMMR       ", "      R  M         JJJ            R      ", "      R            JJJ            R      ", "     R                             R     ", "     R            JJJJJ            R     ", "    R           JJJJJJJJJ           R    ", "    R          JJJ     JJJ          R    ", "   R          JJ   RRR   JJ          R   ", "   R  M       JJ  RQQQR  JJ       M  R   ", "   R         JJ  RQQQQQR  JJ         R   ", "   R   JJ    JJ RQQQQQQQR JJ    JJ   R   ", "   R  JJJ    JJ RQQQQQQQR JJ    JJJ  R   ", "   R   JJ    JJ RQQQQQQQR JJ    JJ   R   ", "   R         JJ  RQQQQQR  JJ         R   ", "   R  M       JJ  RQQQR  JJ       M  R   ", "   R          JJ   RRR   JJ          R   ", "    R          JJJ     JJJ          R    ", "    R           JJJJJJJJJ           R    ", "     R            JJJJJ            R     ", "     R                             R     ", "      R            JJJ            R      ", "      R            JJJ         M  R      ", "       RMMM                    M R       ", "        R                      MR        ", "         R                     R         ", "          RR     M  J  M     RR          ", "            RR             RR            ", "              RR         RR              ", "                RRRRRRRRR                ", "                                         ", "                                         ", "                                         ")
        .aisle("                                         ", "                                         ", "                                         ", "                RRRRRRRRR                ", "             RRR         RRR             ", "            R               R            ", "          RR      M J M      RR          ", "        MR                     R         ", "        R                       RM       ", "       R J                   M J R       ", "      R            JJJ       M    R      ", "      R  MM        JJJ            R      ", "     R                             R     ", "    R             JJJJJ             R    ", "    R           JJJJJJJJJ           R    ", "    R          JJJ     JJJ          R    ", "   R          JJ   RRR   JJ          R   ", "   R          JJ  RQQQR  JJ          R   ", "   R  M      JJ  RQQQQQR  JJ      M  R   ", "   R   JJ    JJ RQQQQQQQR JJ    JJ   R   ", "   R  JJJ    JJ RQQQQQQQR JJ    JJJ  R   ", "   R   JJ    JJ RQQQQQQQR JJ    JJ   R   ", "   R  M      JJ  RQQQQQR  JJ      M  R   ", "   R          JJ  RQQQR  JJ          R   ", "   R          JJ   RRR   JJ          R   ", "    R          JJJ     JJJ          R    ", "    R           JJJJJJJJJ           R    ", "    R             JJJJJ             R    ", "     R                             R     ", "      R            JJJ        MM  R      ", "      R    M       JJJ            R      ", "       R J M                   J R       ", "       MR                       R        ", "         R                     RM        ", "          RR      M J M      RR          ", "            R               R            ", "             RRR         RRR             ", "                RRRRRRRRR                ", "                                         ", "                                         ", "                                         ")
        .aisle("                                         ", "                                         ", "                                         ", "                RRRRRRRRR                ", "              RR         RR              ", "            RR             RR            ", "          RR      JJJJJ      RR M        ", "       M R                     R M       ", "      M R                       R        ", "       RJJ                     JJR       ", "      R  J  M      JJJ         J  R      ", "      R    M       JJJ       M    R      ", "     R                        M    R     ", "     R            JJJJJ            R     ", "    R           JJJJJJJJJ           R    ", "    R          JJJ     JJJ          R    ", "   R          JJ   RRR   JJ          R   ", "   R          JJ  RQQQR  JJ          R   ", "   R  J      JJ  RQQQQQR  JJ      J  R   ", "   R  JJJ    JJ RQQQQQQQR JJ    JJJ  R   ", "   R  JJJ    JJ RQQQQQQQR JJ    JJJ  R   ", "   R  JJJ    JJ RQQQQQQQR JJ    JJJ  R   ", "   R  J      JJ  RQQQQQR  JJ      J  R   ", "   R          JJ  RQQQR  JJ          R   ", "   R          JJ   RRR   JJ          R   ", "    R          JJJ     JJJ          R    ", "    R           JJJJJJJJJ           R    ", "     R            JJJJJ            R     ", "     R    M                        R     ", "      R    M       JJJ       M    R      ", "      R            JJJ      M  J  R      ", "       R JK                    JJR       ", "        R                      PR M      ", "       M R                     R M       ", "        M RR      JJJJJ      RR          ", "            RR             RR            ", "              RR         RR              ", "                RRRRRRRRR                ", "                                         ", "                                         ", "                                         ")
        .aisle("                                         ", "                                         ", "                                         ", "                 RRRRRRR                 ", "              RRR       RRR              ", "            RR             RR            ", "          RR      NJ JN      RRM         ", "         R                     R         ", "        R   M                  JR        ", "      MRJJJ M                 JJ R       ", "      R            JJJ            R      ", "      R            JJJ            R      ", "     R                         MM  R     ", "     R                             R     ", "    R                               R    ", "    R                               R    ", "    R                               R    ", "   R               RRR               R   ", "   R  N           RQQQR           N  R   ", "   R  JJJ        RQQQQQR        JJJ  R   ", "   R   JJ        RQQQQQR        JJ   R   ", "   R  JJJ        RQQQQQR        JJJ  R   ", "   R  N           RQQQR           N  R   ", "   R               RRR               R   ", "    R                               R    ", "    R                               R    ", "    R                               R    ", "     R                             R     ", "     R  MM                         R     ", "      R            JJJ            R      ", "      R            JJJ            R      ", "       RJJJ                 M JJ RM      ", "        R                   M  JR        ", "         R                     R         ", "         MRR      NJ JN      RR          ", "            RR             RR            ", "              RRR       RRR              ", "                 RRRRRRR                 ", "                                         ", "                                         ", "                                         ")
        .aisle("                                         ", "                                         ", "                                         ", "                 RRRRRRR                 ", "              RRR       RRR              ", "            RR     P P     RR            ", "          RR      NP PN      RR          ", "         R M       J P       M R         ", "        RP                      R        ", "       R J                    KJ R       ", "      R  K         JJJ         J  R      ", "      RM           JJJ           MR      ", "     R                             R     ", "     R                             R     ", "    R                               R    ", "    R                               R    ", "    R                               R    ", "   R              M   M              R   ", "   R  N          M RRR M          N  R   ", "   R PPJJ         RQQQR         JJPP R   ", "   R   JJ         RQQQR         JJ   R   ", "   R PPJJ         RQQQR         JJPP R   ", "   R  N          M RRR M          N  R   ", "   R              M   M              R   ", "    R                               R    ", "    R                               R    ", "    R                               R    ", "     R                             R     ", "     R                             R     ", "      RM           JJJ           MR      ", "      R  P         JJJ            R      ", "       RJJ                     J R       ", "        RJ                      R        ", "         R M       J P       M R         ", "          RR      NP PN      RR          ", "            RR     P P     RR            ", "              RRR       RRR              ", "                 RRRRRRR                 ", "                                         ", "                                         ", "                                         ")
        .aisle("                                         ", "                                         ", "                                         ", "                   RRR                   ", "               RRRR   RRRR               ", "             RR    P P    RR             ", "          MRR    NPP JPN    RR           ", "         RR        P P        RR         ", "        RP                  M  PR        ", "       RPJ                    PJJR       ", "       R                       J RM      ", "      R    X       JJJ       X    R      ", "      R M          JJJ            R      ", "     R                             R     ", "     R                             R     ", "    R                               R    ", "    R                               R    ", "    R N                           N R    ", "    R P           M   M           P R    ", "   R PPPJJ         RRR         JJPPP R   ", "   R    JJ         RRR         JJ    R   ", "   R PJPJJ         RRR         JJPJP R   ", "    R P           M   M           P R    ", "    R N                           N R    ", "    R                               R    ", "    R                               R    ", "     R                             R     ", "     R                             R     ", "      R            JJJ          M R      ", "      R    X       JJJ       X    R      ", "      MR P                     J R       ", "       RPJP                   PJPR       ", "        RJ  M                  JR        ", "         RR        P P        RR         ", "           RR    NPP JPN    RRM          ", "             RR    P P    RR             ", "               RRRR   RRRR               ", "                   RRR                   ", "                                         ", "                                         ", "                                         ")
        .aisle("                                         ", "                                         ", "                                         ", "                                         ", "                RRRRRRRRR                ", "             RRR   J P   RRR             ", "        NN RR    NPN NPN    RR           ", "          R        P P        R          ", "         R                     R  N      ", "        RPJ                 M PPR N      ", "       R P                  M    R       ", "      R    X       JJJ       X    R      ", "      R  MM        JJJ            R      ", "     R                             R     ", "     R                             R     ", "     R                             R     ", "    R                               R    ", "    R N                           N R    ", "    R P                           P R    ", "    RJNPJJ         N N         JJPNJR    ", "    R   JJ          N          JJ   R    ", "    RPNPJJ         N N         JJPNPR    ", "    R P                           P R    ", "    R N                           N R    ", "    R                               R    ", "     R                             R     ", "     R                             R     ", "     R                             R     ", "      R            JJJ        NN  R      ", "      R    X       JJJ       X    R      ", "       R K  N                  J R       ", "      M RPJ N                 PPR        ", "      M  R                     R         ", "          R        P P        R          ", "           RR    NPN NPN    RR MM        ", "             RRR   J P   RRR             ", "                RRRRRRRRR                ", "                                         ", "                                         ", "                                         ", "                                         ")
        .aisle("                                         ", "                                         ", "                                         ", "                                         ", "                 RRRRRRR                 ", "              RRR PP PK RRR              ", "            RR   NPN NPN   RR   N        ", "       N  RR      PK JP      RR  N       ", "      N  R                     R         ", "        RPJ                    PR        ", "       R PX N                 XJ R       ", "       R   M                 M   R       ", "      R            JJJ        N   R      ", "      R            JJJ            R      ", "     R                             R     ", "     R                             R     ", "     R                             R     ", "    R N                           N R    ", "    RPPP                         PPPR    ", "    RPNKJJJ                   JJJKNPR    ", "    R   JJJ         N         JJJ   R    ", "    RPNJJJJ                   JJJJNPR    ", "    RKPP                         PPKR    ", "    R N                           N R    ", "     R                             R     ", "     R                             R     ", "     R                             R     ", "      R            JJJ            R      ", "      R   N        JJJ            R      ", "       R   N                 N   R       ", "       R PX                 N X  R       ", "        RPJ                   PPR        ", "         R                     R  N      ", "       M  RR      PK JP      RR  M       ", "        N   RR   NPN NPN   RR            ", "              RRR PP PK RRR              ", "                 RRRRRRR                 ", "                                         ", "                                         ", "                                         ", "                                         ")
        .aisle("                                         ", "                                         ", "                                         ", "                                         ", "                    R                    ", "               RRRRR RRRRR               ", "             RR  PPN NPP  RR  NN         ", "           RR     PN NP     RR           ", "          R N                 R          ", "      N  RP N                 XR         ", "      N RXX                   XPR        ", "       R                         R       ", "       R                       NNR       ", "      R            JJJ            R      ", "      R            JJJ            R      ", "     R                             R     ", "     R                             R     ", "     RP                           PR     ", "     RPP                         PPR     ", "     RNN JJ                   JJ NNR     ", "    R    JJ         O         JJ    R    ", "     RNN JJ                   JJ NNR     ", "     RPP                         PPR     ", "     RP                           PR     ", "     R                             R     ", "     R                             R     ", "      R            JJJ            R      ", "      R            JJJ            R      ", "       RNN                       R       ", "       R                         R       ", "        RXX                   XXR N      ", "         RJ                 N KRP N      ", "         PR                 N R          ", "           RR     PN NP     RR           ", "         NN  RR  PPN NPP  RR             ", "               RRRRR RRRRR               ", "                    R                    ", "                                         ", "                                         ", "                                         ", "                                         ")
        .aisle("                                         ", "                                         ", "                                         ", "                                         ", "                                         ", "                 RRRRRRR                 ", "          N  RRRRPP   PPRRR              ", "           NR    PP   PK   RRN           ", "         P R                NR P         ", "        PPR                   RPP        ", "         R                     R  N      ", "       NR                       RN       ", "       RN                        R       ", "       R                         R       ", "      R            JJJ            R      ", "      R            JJJ            R      ", "      R            JJJ            R      ", "     RPP                         PPR     ", "     RPP                         PPR     ", "     R    JJ        O        JJ    R     ", "     R    JJ       OOO       JJ    R     ", "     R    JJ        O        JJ    R     ", "     RPP                         PPR     ", "     RPK                         KPR     ", "      R            JJJ            R      ", "      R            JJJ            R      ", "      R            JJJ            R      ", "       R                         R       ", "       R                        NR       ", "       NR                       RN       ", "      N  R                     R         ", "        PPR                   RPK        ", "           RN                R P         ", "           NRR   PP   PK   RRN           ", "              RRRPP   PPRRR   N          ", "                 RRRRRRR                 ", "                                         ", "                                         ", "                                         ", "                                         ", "                                         ")
        .aisle("                                         ", "                                         ", "                                         ", "                                         ", "                                         ", "                KKK   KJK                ", "        NN     RRRRRRRRRRR               ", "             RR KPK   KKK RR             ", "        XP  R               R  PX N      ", "        PKRR                ORRKX N      ", "         R                  O  R         ", "        R                      R         ", "        ROO                     R        ", "       R                         R       ", "       R                         R       ", "      R            JJJ            R      ", "     KRK           JJJ           KRK     ", "     KRP           JJJ           PRK     ", "     KRK           JJJ           KRK     ", "      R   JJJ      JJJ      JJJ   R      ", "      R   JJJ      JJJ      JJJ   R      ", "      R   JJJ      JJJ      JJJ   R      ", "     KRK           JJJ           KRK     ", "     JRK           JJJ           KRJ     ", "     KRK           JJJ           KRK     ", "      R            JJJ            R      ", "       R                         R       ", "       R                         R       ", "        R                     NNR        ", "         R                     R         ", "         R  N                  R         ", "      O KKRRN                RRKK        ", "      O XX  R               R  KX        ", "             RR KPK   KKK RR             ", "               RRRRRRRRRRR     OO        ", "                KKK   KJK                ", "                                         ", "                                         ", "                                         ", "                                         ", "                                         ")
        .aisle("                                         ", "                                         ", "                                         ", "                                         ", "                                         ", "                KP     KK                ", "               OKRRRRRRRKO      O        ", "       OXX    RRRP     KRRR    XXO       ", "      OXXPX  R             R  XKXX       ", "       XXKKRR               RRKKPX       ", "        XKR O                 RXX        ", "         R O                 O R         ", "         R                    OR         ", "        R                       R        ", "       R                         R       ", "      OR                         RO      ", "     KKR                         RKK     ", "     PRP           JJJ           PRP     ", "      R            JJJ            R      ", "      R    JJJJ   PJJJJ   JJJJ    R      ", "      R    JJJJ   JJJJP   JJJJ    R      ", "      R    JJJJ   JJJJJ   JJJJ    R      ", "      R            JJJ            R      ", "     KRK           JJJ           KRK     ", "     KKR                         RKK     ", "      OR                         RO      ", "       R                         R       ", "        R                       R        ", "         RO                    R         ", "         R O                 O R         ", "        XKR                 O RPX        ", "       XXKPRR               RRKKPX       ", "       XXKX  R             R  XKXXO      ", "       OXX    RRRP     KRRR    XXO       ", "        O      OKRRRRRRRKO               ", "                KP     KK                ", "                                         ", "                                         ", "                                         ", "                                         ", "                                         ")
        .aisle("                                         ", "                                         ", "                                         ", "                                         ", "                                         ", "               OKK     KKO               ", "               KKK     KKK    OO         ", "        XX     ORRRRRRRRRO     XX        ", "       XXKX O RR         RR   XKXX       ", "      OXKKK OR             R  JKKX       ", "      O XK RR               RR KX        ", "          RR                 RR          ", "          R                   ROO        ", "         R                     R         ", "        R                       R        ", "     OKOR                       ROKO     ", "     KKR                         RKK     ", "     KKR           PPP           RKK     ", "       R          PPPPP          R       ", "       R     JJJJPPJJPPJJJJJ     R       ", "       R     JJJJPPKKKPPJJJJ     R       ", "       R     JJJJPPPJPPPJJJJ     R       ", "       R          PPJPP          R       ", "     KKR           JPP           RKK     ", "     KKR                         RKK     ", "     OKOR                       ROKO     ", "        R                       R        ", "         R                     R         ", "        OOR                   R          ", "          RR                 RR          ", "        XK RR               RR KX O      ", "       XKKX  R             RO XKXXO      ", "       XXKX   RR         RR O XXXX       ", "        XX     ORRRRRRRRRO     XX        ", "         OO    KKK     KKK               ", "               OKK     KKO               ", "                                         ", "                                         ", "                                         ", "                                         ", "                                         ")
        .aisle("                                         ", "                                         ", "                                         ", "                                         ", "               O         O               ", "               KK       PK               ", "        XXO    KKK     KKK     XX        ", "       XXXXO   KK       JP   OXXXX       ", "      XXXKXX   ORRRRRRRRRO  OXXKXXX      ", "      XXKKXX  RR         RR  XKKJXX      ", "       XXJX  R             R  XKXXO      ", "       OXX  R               R  XXO       ", "        O  R                 R           ", "          R                   R          ", "         R                     R         ", "    OKKKOR                     ROKKKO    ", "     KKKR          PPP          RKKK     ", "      K R         PPPPP         R K      ", "        R        PPKPPPP        R        ", "        R     JJJJJJJJJJJJJ     R        ", "        R     JJJJJJJJJJJJJ     R        ", "        R     JJJJJJJJJJJJJ     R        ", "        R        PPPPPPP        R        ", "      K R         PPPKP         R K      ", "     PKJR          KPP          RJKP     ", "    OKKPOR                     ROPKKO    ", "         R                     R         ", "          R                   R          ", "           R                 R  O        ", "       OXX  R               R  XXO       ", "      OXXXX  R             R  XKXX       ", "      XXXKJX  RR         RR  XKKKXX      ", "      XXXKXXO  ORRRRRRRRRO   XXKXXX      ", "       XXXXO   KK       JP   OXXXX       ", "        XX     KKK     KKK    OXX        ", "               KK       PK               ", "               O         O               ", "                                         ", "                                         ", "                                         ", "                                         ")
        .aisle("                                         ", "                                         ", "                                         ", "                                         ", "               O         O               ", "        YY     KJ       PK     YY        ", "       YOOY    KK       KK    YYYY       ", "      YYYYYY   KK       KK   YYYYYY      ", "     YYYYYYYY  O         O  YYYPYYOY     ", "     YYYPKYYY   RRRRRRRRR   OYKKKYOY     ", "      YYYYYY  RRR       RRR OYYPYYY      ", "       YYYY  RR           RR  YYYY       ", "        YOO RR             RR  YY        ", "           RR               RR           ", "          RR                 RR          ", "    OKKKO R        PPK        R OKKKO    ", "     JKK RR       KKKKK       RR KKJ     ", "         R       KKPKKKP       R         ", "         R      PKJKKKJKK      R         ", "         R     KKJJJJJJJKK     R         ", "         R     KJJJJJJJJKK     R         ", "         R     KKJJJJJJJKP     R         ", "         R      PKPKPKKKK      R         ", "         R       KKJJKKK       R         ", "     PKK RR       KKJJP       RR KKP     ", "    OKKKO R        PKK        R OKKKO    ", "          RR                 RR          ", "           RR               RR           ", "        YY  RR             RR OOY        ", "       YYYY  RR           RR  YYYY       ", "      YYYJYYO RRR       RRR  YYKYYY      ", "     YOYYKKYO   RRRRRRRRR   YYKKKYYY     ", "     YOYYYYYY  O         O  YYYJYYYY     ", "      YYYYYY   KK       KK   YYYYYY      ", "       YYYY    KK       KK    YOOY       ", "        YY     KJ       PK     YY        ", "               O         O               ", "                                         ", "                                         ", "                                         ", "                                         ")
        .aisle("                                         ", "                                         ", "                                         ", "                                         ", "        YY     O         O     YY        ", "       YYYY    JK       KK    YYYY       ", "      YYYYYY   KK       KK   YYYYYY      ", "     YYOYYYYY  KK       KK  YYYYYOYY     ", "    YYYYYJYYYY O         O YYYYKYYYYY    ", "    YYYYYKKYYY             YYYKKKYYYY    ", "     YYYYKYYY    RRRRRRR    YYYKYYYY     ", "      YYYYYO   RRRRRRRRRRR   OYYYYY      ", "       YYYY   RRR       RRR   YYYY       ", "        YY   RR           RR   YY        ", "            RR     KKK     RR            ", "    OJKKO  RR     KKKJK     RR  OKKJO    ", "     KKK   RR    KKKKJPK    RR   KKK     ", "          RR    KKJKKKPKK    RR          ", "          RR   KKKKKPKKKKK   RR          ", "          RR  KKKKPKJJPKKKK  RR          ", "          RR  KKJKKPPJJPKKK  RR          ", "          RR  KKKKKJPPPKKKK  RR          ", "          RR   KKJKKPKKKKK   RR          ", "          RR    KKPKJKKKK    RR          ", "     KKK   RR    KKPKKKK    RR   KKK     ", "    OKKKO  RR     KKKPK     RR  OKKKO    ", "            RR     KKK     RR            ", "        YY   RR           RR   YY        ", "       YYYY   RRR       RRR   YYYY       ", "      YYYYYO   RRRRRRRRRRR   OYYYYY      ", "     YYYYKYYY    RRRRRRR    YYYPYYYY     ", "    YYYYKKYYYY             YYYYKYYYYY    ", "    YYYYYPYYYY O         O YYYYKYYYYY    ", "     YYOYYYYY  KK       KK  YYYYYOYY     ", "      YYYYYY   KK       KK   YYYYYY      ", "       YYYY    JK       KK    YYYY       ", "        YY     O         O     YY        ", "                                         ", "                                         ", "                                         ", "                                         ")
        .aisle("                VVVVVVVVV                ", "             VVVVVVVVVVVVVVV             ", "           VVVVVVVVVVVVVVVVVVV           ", "         VVVVVVVVVVVVVVVVVVVVVVV         ", "        VVVVVVVVVVVVVVVVVVVVVVVVV        ", "       VVVVVVVVVVVVVVVVVVVVVVVVVVV       ", "      VVVVVVVVVVVVVVVVVVVVVVVVVVVVV      ", "     VVVVVVVVVVVVVVVVVVVVVVVVVVVVVVV     ", "    VVVVVVVVVVVVVVVVVVKKKVVVVVVVVVVVV    ", "   VVVVVVVVVVVVVVVVKKKPPPKVVVVVVVVVVVV   ", "   VVVVVVVVVVVVVVKKPPPJJJPKVVVVVVVVVVV   ", "  VVVVVVVVVVVVVVKPPJJJPPPKVVVVVVVVVVVVV  ", "  VVVVVVVVVVVVVKPRRRRRRRKVVVVVVVVVVVVVV  ", " VVVVVVVVVVVVVKRRRRRKRRRRRKVVVVVVVVVVVVV ", " VVVVVVVVVKVVKRRRKKKPPJJRRRKVVVVVVVVVVVV ", " VVVVVVVVKPKVRRRPKKPJJPPPRRRKVVVVVVVVVVV ", "VVVVVVVVKPJPKRRPKKPJPPKKKPRRPKVVVVVVVVVVV", "VVVVVVVVKPJPRRJPKPJPKKPPKKKRRPKVVVVVVVVVV", "VVVVVVVVKPJPRRJPKPJPKPJJPKKRRPKVVVVVVVVVV", "VVVVVVVVVKPJRRPJPKPJPJPPJPKRRJPKVVVVVVVVV", "VVVVVVVVVKPJRKPJPKKPJPKKPJPKRJPKVVVVVVVVV", "VVVVVVVVVKPJRRKPJPPJPJPKPJPRRJPKVVVVVVVVV", "VVVVVVVVVVKPRRKKPJJPKPJPKPJRRPJPKVVVVVVVV", "VVVVVVVVVVKPRRKKKPPKKPJPKPJRRPJPKVVVVVVVV", "VVVVVVVVVVVKPRRPKKKPPJPKKPRRKPJPKVVVVVVVV", " VVVVVVVVVVVKRRRPPPJJPKKPRRRVKPKVVVVVVVV ", " VVVVVVVVVVVVKRRRJJPPKKKRRRKVVKVVVVVVVVV ", " VVVVVVVVVVVVVKRRRRRKRRRRRKVVVVVVVVVVVVV ", "  VVVVVVVVVVVVVVKRRRRRRRPKVVVVVVVVVVVVV  ", "  VVVVVVVVVVVVVKPPPJJJPPKVVVVVVVVVVVVVV  ", "   VVVVVVVVVVVKPJJJPPPKKVVVVVVVVVVVVVV   ", "   VVVVVVVVVVVVKPPPKKKVVVVVVVVVVVVVVVV   ", "    VVVVVVVVVVVVKKKVVVVVVVVVVVVVVVVVV    ", "     VVVVVVVVVVVVVVVVVVVVVVVVVVVVVVV     ", "      VVVVVVVVVVVVVVVVVVVVVVVVVVVVV      ", "       VVVVVVVVVVVVVVVVVVVVVVVVVVV       ", "        VVVVVVVVVVVVVVVVVVVVVVVVV        ", "         VVVVVVVVVVVVVVVVVVVVVVV         ", "           VVVVVVVVVVVVVVVVVVV           ", "             VVVVVVVVVVVVVVV             ", "                VVVVVVVVV                ")
        .aisle("                VVVV~VVVV                ", "             VVVVVVVVVVVVVVV             ", "           VVVVVVVVVVVVVVVVVVV           ", "         VVVVVVVVVVVVVVVVVVVVVVV         ", "        VVVVVVVVVVVVVVVVVVVVVVVVV        ", "       VVVVVVVVVVVVVVVVVVVVVVVVVVV       ", "      VVVVVVVVVVVVVVVVVVVVVVVVVVVVV      ", "     VVVVVVVVVVVVVVVVVVVVVVVVVVVVVVV     ", "    VVVVVVVVVVVVVVVVVVKKKVVVVVVVVVVVV    ", "   VVVVVVVVVVVVVVVVKKKPPPKVVVVVVVVVVVV   ", "   VVVVVVVVVVVVVVKKPPPJJJPKVVVVVVVVVVV   ", "  VVVVVVVVVVVVVVKPPJJJPPPKVVVVVVVVVVVVV  ", "  VVVVVVVVVVVVVKPJJPPPKKKVVVVVVVVVVVVVV  ", " VVVVVVVVVVVVVKPJPPKRKPPPKKVVVVVVVVVVVVV ", " VVVVVVVVVKVVKPJPRRRRRRRJPPKVVVVVVVVVVVV ", " VVVVVVVVKPKVKPJRRRRRRRRRJJPKVVVVVVVVVVV ", "VVVVVVVVKPJPKPJRRRRJPPRRRRPJPKVVVVVVVVVVV", "VVVVVVVVKPJPKPRRRPJPKKPPRRRPJPKVVVVVVVVVV", "VVVVVVVVKPJPKPRRRPJPKPJJRRRPJPKVVVVVVVVVV", "VVVVVVVVVKPJPKRRPKPJPJPPJRRKPJPKVVVVVVVVV", "VVVVVVVVVKPJPRRRPKKPJPKKPRRRPJPKVVVVVVVVV", "VVVVVVVVVKPJPKRRJPPJPJPKPRRKPJPKVVVVVVVVV", "VVVVVVVVVVKPJPRRRJJPKPJPRRRPKPJPKVVVVVVVV", "VVVVVVVVVVKPJPRRRPPKKPJPRRRPKPJPKVVVVVVVV", "VVVVVVVVVVVKPJPRRRRPPJRRRRJPKPJPKVVVVVVVV", " VVVVVVVVVVVKPJJRRRRRRRRRJPKVKPKVVVVVVVV ", " VVVVVVVVVVVVKPPJRRRRRRRPJPKVVKVVVVVVVVV ", " VVVVVVVVVVVVVKKPPPKRKPPJPKVVVVVVVVVVVVV ", "  VVVVVVVVVVVVVVKKKPPPJJPKVVVVVVVVVVVVV  ", "  VVVVVVVVVVVVVKPPPJJJPPKVVVVVVVVVVVVVV  ", "   VVVVVVVVVVVKPJJJPPPKKVVVVVVVVVVVVVV   ", "   VVVVVVVVVVVVKPPPKKKVVVVVVVVVVVVVVVV   ", "    VVVVVVVVVVVVKKKVVVVVVVVVVVVVVVVVV    ", "     VVVVVVVVVVVVVVVVVVVVVVVVVVVVVVV     ", "      VVVVVVVVVVVVVVVVVVVVVVVVVVVVV      ", "       VVVVVVVVVVVVVVVVVVVVVVVVVVV       ", "        VVVVVVVVVVVVVVVVVVVVVVVVV        ", "         VVVVVVVVVVVVVVVVVVVVVVV         ", "           VVVVVVVVVVVVVVVVVVV           ", "             VVVVVVVVVVVVVVV             ", "                VVVVVVVVV                ")
        .aisle("                VVVVVVVVV                ", "             VVVVVVVVVVVVVVV             ", "           VVVVVVVVVVVVVVVVVVV           ", "         VVVVVVVVVVVVVVVVVVVVVVV         ", "        VVVVVVVVVVVVVVVVVVVVVVVVV        ", "       VVVVVVVVVVVVVVVVVVVVVVVVVVV       ", "      VVVVVVVVVVVVVVVVVVVVVVVVVVVVV      ", "     VVVVVVVVVVVVVVVVVVVVVVVVVVVVVVV     ", "    VVVVVVVVVVVVVVVVVVKKKVVVVVVVVVVVV    ", "   VVVVVVVVVVVVVVVVKKKPPPKVVVVVVVVVVVV   ", "   VVVVVVVVVVVVVVKKPPPJJJPKVVVVVVVVVVV   ", "  VVVVVVVVVVVVVVKPPJJJPPPKVVVVVVVVVVVVV  ", "  VVVVVVVVVVVVVKPJJPPPKKKVVVVVVVVVVVVVV  ", " VVVVVVVVVVVVVKPJPPKKKPPPKKVVVVVVVVVVVVV ", " VVVVVVVVVKVVKPJPKKKPPJJJPPKVVVVVVVVVVVV ", " VVVVVVVVKPKVKPJPKKPJJPPPJJPKVVVVVVVVVVV ", "VVVVVVVVKPJPKPJPKKPRRRKKKPPJPKVVVVVVVVVVV", "VVVVVVVVKPJPKPJPKRRRRRRRKKKPJPKVVVVVVVVVV", "VVVVVVVVKPJPKPJPKRRRRRRRPKKPJPKVVVVVVVVVV", "VVVVVVVVVKPJPKPJRRRRRRRRRPKKPJPKVVVVVVVVV", "VVVVVVVVVKPJPKPJRRRRRRRRRJPKPJPKVVVVVVVVV", "VVVVVVVVVKPJPKKPRRRRRRRRRJPKPJPKVVVVVVVVV", "VVVVVVVVVVKPJPKKPRRRRRRRKPJPKPJPKVVVVVVVV", "VVVVVVVVVVKPJPKKKRRRRRRRKPJPKPJPKVVVVVVVV", "VVVVVVVVVVVKPJPPKKKRRRPKKPJPKPJPKVVVVVVVV", " VVVVVVVVVVVKPJJPPPJJPKKPJPKVKPKVVVVVVVV ", " VVVVVVVVVVVVKPPJJJPPKKKPJPKVVKVVVVVVVVV ", " VVVVVVVVVVVVVKKPPPKKKPPJPKVVVVVVVVVVVVV ", "  VVVVVVVVVVVVVVKKKPPPJJPKVVVVVVVVVVVVV  ", "  VVVVVVVVVVVVVKPPPJJJPPKVVVVVVVVVVVVVV  ", "   VVVVVVVVVVVKPJJJPPPKKVVVVVVVVVVVVVV   ", "   VVVVVVVVVVVVKPPPKKKVVVVVVVVVVVVVVVV   ", "    VVVVVVVVVVVVKKKVVVVVVVVVVVVVVVVVV    ", "     VVVVVVVVVVVVVVVVVVVVVVVVVVVVVVV     ", "      VVVVVVVVVVVVVVVVVVVVVVVVVVVVV      ", "       VVVVVVVVVVVVVVVVVVVVVVVVVVV       ", "        VVVVVVVVVVVVVVVVVVVVVVVVV        ", "         VVVVVVVVVVVVVVVVVVVVVVV         ", "           VVVVVVVVVVVVVVVVVVV           ", "             VVVVVVVVVVVVVVV             ", "                VVVVVVVVV                ")
        .where('~', selfPredicate())
        .where('V', states(casingState))
        .where('Y', states(casingState))
        .where('X', states(secondCasingState))
        .where('R', states(glassState))
        .where('J', states(fourthCasingState))
        .where('K', states(thirdCasingState))
        .where('P', states(thirdCasingState))
        .where('Q', states(coilState))
        .where('M', frames(Bedrockium))
        .where('N', frames(TranscendentMetal))
        .where('O', frames(Neutronium))
        .where(' ', any())
        .build()

    // @formatter:on

    @SideOnly(Side.CLIENT)
    override fun getBaseTexture(sourcePart: IMultiblockPart?): ICubeRenderer = GTLiteOverlays.LATTICE_QCD_THERMAL_SHIELDING_CASING

    @SideOnly(Side.CLIENT)
    override fun addInformation(stack: ItemStack, world: World?, tooltip: MutableList<String>, advanced: Boolean)
    {
        super.addInformation(stack, world, tooltip, advanced)
        tooltip.add(I18n.format("gtlitecore.tooltip.machine.machine_type",
                                I18n.format("gtlitecore.machine.nano_forge.additional_structure_name")))
        tooltip.add(I18n.format("gtlitecore.machine.virtual_gestalt_computing_uplink.tooltip.1"))
    }
}